---

# 1. 에러와 오류

프로그램이 실행 중 어떤 원인에 의해서 오작동을 하거나 비정상적으로 종료되는 경우가 있다. 이러한 결과를 초래하는 원인을 프로그램 오류라고 한다.

에러는 아래 3가지 종류가 있다.

- **컴파일 에러** : 컴파일 시에 발생하는 에러
- **런타임 에러** : 실행 시에 발생하는 에러
- 논리적 에러 : 실행은 되지만 의도와 다르게 동작하는 것

컴파일 에러는 소스 코드를 컴파일 하면 컴파일러가 소스코드의 오타나 잘못된 구문 등 기본적 검사를 수행하여 알려준다. 하지만 컴파일시 문제가 없어도 실행 중 발생하는 잠재적인 에러가 있기 마련인데 이를 런타임 에러라고 한다. 런타임 에러는 프로그램의 실행도중 발생할 수 있는 경우의 수를 체크하여 이에대한 대비를 해야하는데 이것이 exception의 기본적인 컨셉이다

## 1-2. 자바에서의 에러와 오류

자바는 런타임 에러를 Error와 Exception으로 분리해서 구분한다.

<aside>
💣 **Error는 프로그램 코드에 의해 수습될 수 없는 심각한 오류이다.
예 ) StackOverflowError, OutOfMemoryError**

</aside>

<aside>
💣 **Exception은 프로그램 코드에 의해 수습될 수 있는 다소 미약한 오류이다.
예 ) NullPointException같은 Exception의 자손**

</aside>

$\color{#46de9b}\rule{500px}{5px}$

# 2. 예외 Class의 계층 구조

예외 클래스에서 주목해야할 점은 하기 2가지이다.

1. 자바는 오류와 에러를 다르게 본다. 따라서 Exception과 Error은 같은 클래스가 아니다.
2. Exception 클래스은 Exception 클래스와 그 자손들과 RuntimeException과 그 자손들로 구분할 수 있다.

    <aside>
    💣 RuntimeException과 그 자손들 : 프로그래머의 실수와 같은 인적 요소에 의해 발생되는 경우가 많음

    </aside>

    <aside>
    💣 나머지 Exception의 자손들 : 외부 요소에 의해 발생되는 경우가 많음, 존재하지 않은 파일의 입력 등등

    </aside>


Object

- Throwable
    - **Exception**
        - **RuntimeException**
            - NullPointException
        - IOException
        - …
    - **Error**
        - OutOufMemoryError
        - …

$\color{#46de9b}\rule{500px}{5px}$

# 3. Exception Handling

<aside>
💣 프로그램 실행 시 발생할 수 있는 예기치 못한 예외의 발생에 대비한 코드를 작성하는 것이다. 
예외 처리는 크게 아래 2가지 목적을 가진다.
1. 프로그램의 비정상적 종료 방지
2. 프로그램의 정상 실행 보장

</aside>

코드에서 처리되지 못한 예외는 JVM의 예외처리기 ( UncaughtExceptionHandler )가 받아서 예외의 원인을 화면에 출력한다. 따라서 코드상의 적절한 예외 처리는 필수적이다. 아래는 자바에서 사용되는 예외처리 문법을 정리한 것이다.

$\color{skyblue}\rule{500px}{5px}$

1. `try-catch`


    - 기본 문법
        1. try 블록 :  예외 처리가 필요한 코드를 적는다. 
        2. catch 블록 : 예외 발생 시 실행될 코드를 적는다,
        3. catch 블록의 실행 
            - try 블록 내부 문장 실행 중 예외가 발생하면 발생한 예외와 catch 블록의 참조변수를 instanceof 연산자로 체크하여 일치하는 연산자면 catch문을 실행한 후 전체 try-catch문을 빠져나온다. 찾지 못하면 예외는 처리되지 못한다.
            - instanceof 연산자로 체크하기 때문에 **Exception 참조변수로 정의한 catch 블록은 모든 예외를 받는다**
                - 나오는 매개변수 : 발생한 예외임
    - try-catch문 내부에서의 흐름
        - `try-catch` 문 안에서 예외 발생
            1. 발생하는 예외와 일치하는 catch 블록이 있는지 체크
            2. 일치하는 catch 블록을 찾게 되면 그 catch 내의 문장을 실행하고, 전체 `try-catch` 문을 빠져나가서 다음 코드 실행, 
                1. catch 블록을 찾았다면 그 catch 내의 문장을 실행하고, 전체 `try-catch` 문을 빠져나가서 다음 코드 실행
                    - 따라서 예외 발생 후 다음 문장은 실행되지 못한다.
                        
                        ```java
                        @Test
                        @DisplayName( "기본 예외 처리 문법 2 : ,예외가 발생후 try-catch문을 빠져나오기 때문에 예외 발생 문장 다음을 실행되지 않는다." )
                        public void exceptionError2 () {
                        		
                        		try {
                        				
                        				for ( int i = 0; i < 3; i++ ) {
                        						
                        						if ( i == 0  ) {
                        								System.out.println( i );
                        						}
                        						else if ( i == 1  ) {
                        								//ArithmeticException 발생
                        								int throwFail = 0/0;
                        						}
                        						else if ( i == 2 ) {
                        								fail( "예외가 발생 후 try-catch를 빠져나온다." );
                        						}
                        						
                        				}
                        				
                        		}
                        		catch ( ArithmeticException e ) {
                        				System.out.println( e.getMessage() );
                        ```
                        
                2. catch 블록이 없다면 해당 예외는 처리되지 못한다.
        - try 블록 내에서 예외가 발생하지 않은 경우 catch 블록 실행되지 않고 그대로 실행
    
    ```java
    try {
    	// 예외 처리가 필요한 코드
    }
    // 예외 발생시 instanceof 연산자로 발생된 예외 클래스와 일치하는 참조 변수를 찾는다.
    // 발생한 예외 instanceof catch 참조변수 
    // -> 따라서 **Exception 참조변수로 정의한 catch 블록은 모든 예외를 받는다**
    catch ( 처리하고자 하는 예외 클래스 타입 e ) {
    	// 예외 발생시 처리
    }
    ```
    
    ```java
    try {
    
    }
    catch ( ExceptionA A ) {
    	// Exception A 발생시 처리하기 위한 블록
    }
    catch ( ExceptionB B ) {
    	// Exception B 발생시 처리하기 위한 블록
    }
    ```

2. `멀티 catch`문


    - ( ~JDK 1.7  )
        
        ```java
        try {
        
        }
        catch ( NullPointException E ) {
        
        }
        catch ( Exception E ) {
        
        }
        ```
        
    - ( JDK 1.7 ~ )
        
        ```java
        try {
        
        }
        catch ( NullPointException | IOExceptoin E ) {
        
        }
        ```
        
        - 예
            
            ```java
            @Test
            @DisplayName( "자바 1.7 이후의 다중 catch 문" )
            public void multiCatchTest () {
            		
            		try {
            				int throwFail = 0/0;
            		}
            		catch ( NullPointerException | ArithmeticException e ) {
            				assertThat( e ).isInstanceOf( ArithmeticException.class );
            		}
            }
            ```
            
        - 멀티 catch 블록 사용시 주의 사항
            - 멀티 catch문은 부모 예외 클래스와 함께 사용할 수 없다. 당연히 불필요한 코드이기 때문
                
                ```java
                @Test
                @DisplayName( "자바 1.7 이후의 다중 catch 문 : 부모 Exception과 사용하는 것은 불필요한 코드기 때문에 컴파일 오류 발생" )
                public void multiCatchTest2 () {
                		
                		// Types in multi-catch must be disjoint: 'java.lang.NullPointerException' is a subclass of 'java.lang.Exception'
                //				try {
                //						int throwFail = 0/0;
                //				}
                //				catch ( NullPointerException | Exception e ) {
                //						assertThat( e ).isInstanceOf( ArithmeticException.class );
                //				}
                }
                ```
                
            - 조상 예외 클래스에서 선언된 것만 사용 가능
                
                ```java
                @Test
                @DisplayName( "자바 1.7 이후의 다중 catch 문 : 묶인 Exception이 다르다면 조상 예외 클래스에서 선언된 것만 사용 가능" )
                public void multiCatchTest3 () {
                		
                		try {
                				int throwFail = 0/0;
                		}
                		catch ( AnnotationTypeMismatchException | ArithmeticException e ) {
                				
                				// Cannot resolve method 'foundType' in 'RuntimeException'
                				/**
                				 * AnnotationTypeMismatchException에만 foundType 메소드 존재, 멀티 catch문에는 사용할 수 없음 여
                				 * 여기서 사용 가능한 것은 전부 두 Exception의 공통 조상인 RuntimeException 클래스의 메소드
                				 * */
                				// e.foundType()
                				if ( e instanceof AnnotationTypeMismatchException ) {
                						AnnotationTypeMismatchException e1 = (AnnotationTypeMismatchException) e;
                						e1.foundType();
                				}
                				else {
                						assertThat( true ).isTrue();
                				}
                		}
                }
                ```

3. 예외 발생


    ```java
    // 1. new 연산자로 발생시키려는 Exception 인스턴스 생성
    Exception e = new Exception( "고의 발생 예외" );
    // 2. throw를 이용해서 예외 발생
    throw e;
    
    // 하나로 합쳐서 사용 가능
    throw new Exception( "고의 발생 예와" );
    ```
    
    - 예
        
        ```java
        @Test
        @DisplayName( "예외 발생 시키기 : throw" )
        public void throwErrorTest () {
        		
        		// 문법 1
        		try {
        				Exception e = new Exception( "고의 예외 발생" );
        				throw e;
        		}
        		catch ( Exception e ) {
        				
        				System.out.println( e.getClass() );
        				assertThat( e ).isExactlyInstanceOf( Exception.class );
        		}
        		
        		// 문법 2
        		try {
        				throw new ArithmeticException( "고의 예외 발생" );
        		}
        		catch ( Exception e ) {
        				
        				System.out.println( e.getClass() );
        				assertThat( e ).isExactlyInstanceOf( ArithmeticException.class );
        		}
        }
        ```

4. 메소드 예외 처리


    ```java
    [접근제어자] [반환타입] [메소드이름]() throws Exception1, Exception2.... , ExceptionN {} 
    ```

5. `finally` 문


    ```java
    try {
    	//... 예외가 발생할 가능성이 있는 문장을 적는다.
    }
    catch  ( Exception E ) {
    	// ... 예외처리를 위한 문장을 적는다.
    }
    finally {
    	// 예외 발생여부와 상관없이 항상 실행되어야 하는 문장을 넣는다.
    }
    ```


$\color{skyblue}\rule{500px}{5px}$

## 3-1. `try-catch`문

- 문법
    1. catch 블록 안에 try catch 블록 사용 가능
        - 예

            ```java
            catch ( NullPointerException e ) {
            						
            						e = null;
            						
            						try {
            								System.out.println(e.getMessage() );
            						}
            						catch ( Exception e1 ) {
            								// catch 블록 내부는 상위 catch 블록의 범위를 가짐 : 중복 불가
            								assertThat( true ).isTrue();
            						}
            						
            				}
            ```

    2. catch 블록안의 변수는 블록 안에서만 유효
- `try-catch`문 예

    ```java
    @Test
    @DisplayName( "기본 예외 처리 문법 1 : 여러 catch 블록 중 현재 Excpetion 블록을 잡는다." )
    public void exceptionTest() {
    		
    		try {
    				ExceptionTestInfo info = new ExceptionTestInfo();
    				
    				String test = info.nullInfo.toString();
    				
    				System.out.println( test );
    		}
    		catch ( NullPointerException e ) {
    				assertThat( true ).isTrue();
    				
    		}
    		catch ( Exception e ) {
    				fail( "이 Catch 블록은 실행되지 않습니다." );
    		}
    }
    ```


## 3-2. 멀티 catch문 ( 자바 1.7 ~ )

자바 1.7 이전에는 다양한 케이스의 예외 처리를 진행하기 위해서 예외마다 catch 블록을 지정해야 했으나 1.7 이후에는 **하나의 catch 블록으로 합칠 수 있다. 이를 멀티 catch 블록이라고 한다.**

## 3-3. 예외의 발생

- 문법

## 3-4. check Exception과 unchecked Exception

예외를 발생시키면 기본적으로 컴파일러는 예외 처리를 강제한다.

```java
@Test
@DisplayName( "checked Exception : 예외처리를 강제하는 것들, RuntimeException과 그 자손이 아닌 것들이 이 경우" )
public void checkedExceptionTest () {
		
		/**
		 * RuntimeException이 아닌 IOException은 반드시 예외 처리가 강제된다. 이를 checkedException이라고 한다.
		 * 이를 checkexception이라고 한다.
		 * Unhandled exception: java.io.IOException
		 * */
		try {
				throw new IOException();
		}
		catch ( IOException e ) {
				assertThat( true ).isTrue();
		}
}
```

하지만 RuntimeException과 그 자손들은 예외처리를 강제하지 않는다. 따라서 예외처리를 하지 않고 컴파일이 가능하다.

```java
@Test
@DisplayName( "unchecked Exception : 예외처리를 강제하지 않는 것들, RuntimeException과 그 자손" )
public void uncheckedExceptionTest () {
		
		/**
		 * RuntimeException과 그 자손들은 예외처리를 하지 않아도 된다.이를 uncheckException이라고 한다.
		 * Unhandled exception: java.io.IOException
		 * */
		assertThrows( NullPointerException.class ,  () -> { throw new NullPointerException(); } );
		
}
```

이때 **예외처리를 확인하지 않는 RuntimeException과 그 자손들을 unchecked Exception, 그 이외에 예외 처리를 강제하는 Exception 클래스를 checked Exception 이라고 한다.**

## 3-5. 메소드의 예외 선언

기존의 `try-catch` 문은 특정 코드에서 예외가 발생할 것을 예측하여 예외 처리를 하는 방법이었다. **메소드에 예외를 선언하는 방법은 메소드 선언부에 throws 키워드를 사용해서 메소드를 사용하는 곳에서 예외 처리를 강제할 수 있다.**

메소드에 예외 선언을 한다는 것은 아래 2가지 의미를 지닌다.

1. 이러한 타입의 예외가 발생할 수 있다는 것을 사용자 측에 알리는 것
2. 발생할 수 있는 예외를 사용자 측에게 예외 처리 강제

사용자 측에서도 받은 예외를 throws로 다시 메소드 예외 선언을 할 수 있다. 하지만 이를 적적하게 처리하지 않으면 main 메소드 마저 종료되어 프로그램 전체가 종료된다.

모든 Java API 문서는 아래와 같이 메소드 예외 선언 정보를 다룬다.

![Untitled](https://s3-us-west-2.amazonaws.com/secure.notion-static.com/2d8b81d8-0f96-4815-b507-b012dd56ed50/Untitled.png)

## 3-6. `finally` 블록

<aside>
💣 finally 블록은 예외의 발생여부와 상관 없이 실행되어야 할 코드를 포함시킬 목적으로 사용된다.

</aside>

보통 파일 생성 코드에서 예외 발생시 예외가 발생한 파일을 삭제하는 코드 finally에 넣는다.

## 3-7. `try-catch-resources` 문 (JDK 1.7 ~)

자동 자원 반환이라고도 한다.

I/O와 같이 입출력을 다루는 클래스를 다루는데 유용하다. 입출력을 사용시 반드시 닫아줘야하는 코드가 있는데 그래야만 사용되었던 resources가 반환되기 때문이다.

<aside>
💣 AutoCloseable 인터페이스를 구현한 클래스는 자동 자원 반환문을 사용해서 자동으로 자원을 반환받을 수 있다.

</aside>

```java
// AutoCloseable 인터페이스를 구현한 클래스만 사용 가능
try ( AutoCloseableClass1 class1 = new AutoCloseableClass1(); 
			AutoCloseableClass2 class2 = new AutoCloseableClass2( class1 ) ) {
	//... 코드 구현
}
catch ( IOException E ) {
	//... Expception
}
```

- 자동 자원 반환 문 사용 전 : finally에 예외 처리 필요, close가 예외 발생시킴

    ```java
    FileInputStream test = null;
    DataInputStream dis = null;
    try {
    		test = new FileInputStream( "test" );
    		dis = new DataInputStream( test );
    }
    catch ( IOException e ) {
    		e.printStackTrace();
    }
    finally {
    		// close가 예외 발생 가능
    		
    		try {
    				if ( dis != null ) dis.close();
    		}
    		catch ( IOException e ) {
    				e.printStackTrace();
    		}
    		
    }
    ```

- 자동 자원 반환 문 사용 후 : 자동으로 닫힘

    ```java
    try ( FileInputStream test1 = new FileInputStream( "test" );
    			DataInputStream dis1 = new DataInputStream( test1 )) {
    		
    		while ( true ) {
    				int score = dis1.readInt();
    				System.out.println( score  );
    		}
    }
    catch ( IOException e ) {
    		e.printStackTrace();
    }
    ```